Workbook

Sheet Coverage Dashboard
A1: PJM 2026/27 | 2025 Reported Heat-Rate Coverage
A3: FINAL 2025 EIA-923 and EIA-860 | Provisional EIA plant/group matches; NOT independently verified PJM unit measurements
A5: COVERAGE METRIC | B5: RESOURCE COUNT
A6: All PJM resource records | B6: =COUNTA('Resource Estimates'!A2:A1300) -> 1299
A7: Nonthermal resources - not applicable | B7: =COUNTIF('Resource Estimates'!AE2:AE1300,"N/A (nonthermal)") -> 507
A8: High-confidence EIA reported plant/group proxies | B8: =COUNTIF('Resource Estimates'!AF2:AF1300,"High – plant proxy") -> 327
A9: Medium-confidence EIA reported plant/group proxies | B9: =COUNTIF('Resource Estimates'!AF2:AF1300,"Medium – plant proxy; confirm") -> 104
A10: Unconfirmed EIA candidate; technology estimate retained | B10: =COUNTIF('Resource Estimates'!AF2:AF1300,"Unconfirmed") -> 119
A11: No usable EIA 2025 data | B11: =COUNTIF('Resource Estimates'!AE2:AE1300,"No usable 2025 EIA fuel/generation") -> 10
A12: No technically compatible EIA candidate | B12: =COUNTIF('Resource Estimates'!AE2:AE1300,"No match") -> 232
A13: Distinct EIA matched plant IDs | B13: 142
A14: Independent PJM unit-specific heat rates verified | B14: 0
A17: INTERPRETATION & NEXT STEPS
A18: 2025 EIA-923 reports plant x prime mover x fuel-group fuel consumption and electricity generation, which may aggregate multiple units.
A19: An accepted PJM-to-EIA match is proposed using names, state, fuel and EIA-860 generator technology. It is not a verified unit identity.
A20: The same EIA group heat rate can appear on several PJM resource rows; do NOT sum those duplicated MWh or fuel inputs.
A21: Workbook Resource Estimates column S divides column R by Q, and column X uses it before falling back to the technology estimate.
A22: For actual unit-level hourly performance, next link EPA CAMPD facility-unit identifiers to PJM/EIA generator equipment.
A23: 2025 reported average net heat rates are not the incremental heat rates used in dispatch bids.
A25: Official data sources
A26: https://www.eia.gov/electricity/data/eia923/
A27: https://www.eia.gov/electricity/data/eia860/

Sheet Resource Estimates
A1: Resource Name | B1: ICAP (MW) | C1: Zone | D1: LDA | E1: PJM Class | F1: Assumed Fuel | G1: Technology | H1: Low HR (MMBtu/MWh) | I1: Base HR (MMBtu/MWh) | J1: High HR (MMBtu/MWh) | K1: Assessment | L1: Assumption Notes | M1: Base Thermal Input at ICAP (MMBtu/h) | N1: Historical Data Status | O1: EIA Plant ID | P1: EIA Plant Name | Q1: 2025 Net Generation (MWh) | R1: 2025 Fuel for Electricity (MMBtu) | S1: 2025 Historical Net HR (MMBtu/MWh) | T1: Match Scope | U1: Fuel / Prime Mover | V1: Historical Data URL | W1: Match / Data Quality Notes | X1: Selected Modeling HR (MMBtu/MWh) | Y1: Selected HR Basis | Z1: Review Flag | AA1: Suggested EIA Match Score | AB1: EIA Plant State | AC1: EIA-860 Generator IDs | AD1: EIA-860 Plant Operable MW | AE1: 2025 Heat Rate Coverage | AF1: EIA Match Confidence | AG1: Original Reported Heat Rate (MMBtu/MWh) | AH1: OUTPUT | AI1: outage adjusted gen | AJ1: RGGI compliance? | AK1: =1-$AL$1 -> 0.62448249 | AL1: 0.37551751 | AT1: RGGI Zones
A2: VIRGINIA OFFSHORE 1 WF | B2: 1.5 | C2: DOM | D2: DOM | E2: Offshore Wind | F2: Wind | G2: Wind turbine | K2: Not applicable | L2: Not applicable: no thermal fuel input | M2: =IF(OR(B2="",I2=""),"",B2*I2) | N2: Not applicable – nonthermal | S2: =IF(AND(ISNUMBER(Q2),Q2>0,ISNUMBER(R2),R2>0),R2/Q2,"") | X2: =IF(ISNUMBER(S2),S2,IF(ISNUMBER(I2),I2,"")) | Y2: =IF(ISNUMBER(S2),"2025 EIA-923 plant/group proxy",IF(ISNUMBER(I2),"Technology estimate","No thermal heat rate")) -> No thermal heat rate | Z2: =IF(ISNUMBER(S2),"Review: NOT unit verified",IF(AE2="No match","No EIA match",IF(AF2="Unconfirmed","Unconfirmed EIA candidate",""))) | AE2: N/A (nonthermal) | AF2: No thermal fuel input | AG2: =IF(ISBLANK(S2),S2,I2) -> 0 | AH2: =B2 -> 1.5 | AI2: =AH2*$AK$1 -> 0.93672374 | AJ2: {=OR(D2=$AT$2:$AT$8)} -> TRUE | AT2: JCPL
A3: ALLEGHENY RIDGE WF | B3: 11.1 | C3: PENELEC | D3: MAAC | E3: Onshore Wind | F3: Wind | G3: Wind turbine | K3: Not applicable | L3: Not applicable: no thermal fuel input | M3: =IF(OR(B3="",I3=""),"",B3*I3) | N3: Not applicable – nonthermal | S3: =IF(AND(ISNUMBER(Q3),Q3>0,ISNUMBER(R3),R3>0),R3/Q3,"") | X3: =IF(ISNUMBER(S3),S3,IF(ISNUMBER(I3),I3,"")) | Y3: =IF(ISNUMBER(S3),"2025 EIA-923 plant/group proxy",IF(ISNUMBER(I3),"Technology estimate","No thermal heat rate")) -> No thermal heat rate | Z3: =IF(ISNUMBER(S3),"Review: NOT unit verified",IF(AE3="No match","No EIA match",IF(AF3="Unconfirmed","Unconfirmed EIA candidate",""))) | AE3: N/A (nonthermal) | AF3: No thermal fuel input | AG3: =IF(ISBLANK(S3),S3,I3) -> 0 | AH3: =AH2+B3 -> 12.6 | AI3: =AH3*$AK$1 -> 7.8684794 | AJ3: {=OR(D3=$AT$2:$AT$8)} -> FALSE | AT3: BGE
A4: ALTA WF | B4: 94 | C4: COMED | D4: COMED | E4: Onshore Wind | F4: Wind | G4: Wind turbine | K4: Not applicable | L4: Not applicable: no thermal fuel input | M4: =IF(OR(B4="",I4=""),"",B4*I4) | N4: Not applicable – nonthermal | S4: =IF(AND(ISNUMBER(Q4),Q4>0,ISNUMBER(R4),R4>0),R4/Q4,"") | X4: =IF(ISNUMBER(S4),S4,IF(ISNUMBER(I4),I4,"")) | Y4: =IF(ISNUMBER(S4),"2025 EIA-923 plant/group proxy",IF(ISNUMBER(I4),"Technology estimate","No thermal heat rate")) -> No thermal heat rate | Z4: =IF(ISNUMBER(S4),"Review: NOT unit verified",IF(AE4="No match","No EIA match",IF(AF4="Unconfirmed","Unconfirmed EIA candidate",""))) | AE4: N/A (nonthermal) | AF4: No thermal fuel input | AG4: =IF(ISBLANK(S4),S4,I4) -> 0 | AH4: =AH3+B4 -> 106.6 | AI4: =AH4*$AK$1 -> 66.569833 | AJ4: {=OR(D4=$AT$2:$AT$8)} -> FALSE | AT4: DOM
A5: ARMENIA MOUNTAIN WF | B5: 14.4 | C5: PENELEC | D5: MAAC | E5: Onshore Wind | F5: Wind | G5: Wind turbine | K5: Not applicable | L5: Not applicable: no thermal fuel input | M5: =IF(OR(B5="",I5=""),"",B5*I5) | N5: Not applicable – nonthermal | S5: =IF(AND(ISNUMBER(Q5),Q5>0,ISNUMBER(R5),R5>0),R5/Q5,"") | X5: =IF(ISNUMBER(S5),S5,IF(ISNUMBER(I5),I5,"")) | Y5: =IF(ISNUMBER(S5),"2025 EIA-923 plant/group proxy",IF(ISNUMBER(I5),"Technology estimate","No thermal heat rate")) -> No thermal heat rate | Z5: =IF(ISNUMBER(S5),"Review: NOT unit verified",IF(AE5="No match","No EIA match",IF(AF5="Unconfirmed","Unconfirmed EIA candidate",""))) | AE5: N/A (nonthermal) | AF5: No thermal fuel input | AG5: =IF(ISBLANK(S5),S5,I5) -> 0 | AH5: =AH4+B5 -> 121 | AI5: =AH5*$AK$1 -> 75.562381 | AJ5: {=OR(D5=$AT$2:$AT$8)} -> FALSE | AT5: PEPCO
A6: BACKBONE MT WF | B6: 8 | C6: APS | D6: RTO | E6: Onshore Wind | F6: Wind | G6: Wind turbine | K6: Not applicable | L6: Not applicable: no thermal fuel input | M6: =IF(OR(B6="",I6=""),"",B6*I6) | N6: Not applicable – nonthermal | S6: =IF(AND(ISNUMBER(Q6),Q6>0,ISNUMBER(R6),R6>0),R6/Q6,"") | X6: =IF(ISNUMBER(S6),S6,IF(ISNUMBER(I6),I6,"")) | Y6: =IF(ISNUMBER(S6),"2025 EIA-923 plant/group proxy",IF(ISNUMBER(I6),"Technology estimate","No thermal heat rate")) -> No thermal heat rate | Z6: =IF(ISNUMBER(S6),"Review: NOT unit verified",IF(AE6="No match","No EIA match",IF(AF6="Unconfirmed","Unconfirmed EIA candidate",""))) | AE6: N/A (nonthermal) | AF6: No thermal fuel input | AG6: =IF(ISBLANK(S6),S6,I6) -> 0 | AH6: =AH5+B6 -> 129 | AI6: =AH6*$AK$1 -> 80.558241 | AJ6: {=OR(D6=$AT$2:$AT$8)} -> FALSE | AT6: PSEG
A7: BEAR CREEK WF | B7: 3.3 | C7: PPL | D7: PPL | E7: Onshore Wind | F7: Wind | G7: Wind turbine | K7: Not applicable | L7: Not applicable: no thermal fuel input | M7: =IF(OR(B7="",I7=""),"",B7*I7) | N7: Not applicable – nonthermal | S7: =IF(AND(ISNUMBER(Q7),Q7>0,ISNUMBER(R7),R7>0),R7/Q7,"") | X7: =IF(ISNUMBER(S7),S7,IF(ISNUMBER(I7),I7,"")) | Y7: =IF(ISNUMBER(S7),"2025 EIA-923 plant/group proxy",IF(ISNUMBER(I7),"Technology estimate","No thermal heat rate")) -> No thermal heat rate | Z7: =IF(ISNUMBER(S7),"Review: NOT unit verified",IF(AE7="No match","No EIA match",IF(AF7="Unconfirmed","Unconfirmed EIA candidate",""))) | AE7: N/A (nonthermal) | AF7: No thermal fuel input | AG7: =IF(ISBLANK(S7),S7,I7) -> 0 | AH7: =AH6+B7 -> 132.3 | AI7: =AH7*$AK$1 -> 82.619033 | AJ7: {=OR(D7=$AT$2:$AT$8)} -> FALSE | AT7: DPL
A8: BEECH RIDGE 2 WF | B8: 7.3 | C8: APS | D8: RTO | E8: Onshore Wind | F8: Wind | G8: Wind turbine | K8: Not applicable | L8: Not applicable: no thermal fuel input | M8: =IF(OR(B8="",I8=""),"",B8*I8) | N8: Not applicable – nonthermal | S8: =IF(AND(ISNUMBER(Q8),Q8>0,ISNUMBER(R8),R8>0),R8/Q8,"") | X8: =IF(ISNUMBER(S8),S8,IF(ISNUMBER(I8),I8,"")) | Y8: =IF(ISNUMBER(S8),"2025 EIA-923 plant/group proxy",IF(ISNUMBER(I8),"Technology estimate","No thermal heat rate")) -> No thermal heat rate | Z8: =IF(ISNUMBER(S8),"Review: NOT unit verified",IF(AE8="No match","No EIA match",IF(AF8="Unconfirmed","Unconfirmed EIA candidate",""))) | AE8: N/A (nonthermal) | AF8: No thermal fuel input | AG8: =IF(ISBLANK(S8),S8,I8) -> 0 | AH8: =AH7+B8 -> 139.6 | AI8: =AH8*$AK$1 -> 87.177756 | AJ8: {=OR(D8=$AT$2:$AT$8)} -> FALSE | AT8: AE
A9: BIG SKY WF | B9: 30.4 | C9: COMED | D9: COMED | E9: Onshore Wind | F9: Wind | G9: Wind turbine | K9: Not applicable | L9: Not applicable: no thermal fuel input | M9: =IF(OR(B9="",I9=""),"",B9*I9) | N9: Not applicable – nonthermal | S9: =IF(AND(ISNUMBER(Q9),Q9>0,ISNUMBER(R9),R9>0),R9/Q9,"") | X9: =IF(ISNUMBER(S9),S9,IF(ISNUMBER(I9),I9,"")) | Y9: =IF(ISNUMBER(S9),"2025 EIA-923 plant/group proxy",IF(ISNUMBER(I9),"Technology estimate","No thermal heat rate")) -> No thermal heat rate | Z9: =IF(ISNUMBER(S9),"Review: NOT unit verified",IF(AE9="No match","No EIA match",IF(AF9="Unconfirmed","Unconfirmed EIA candidate",""))) | AE9: N/A (nonthermal) | AF9: No thermal fuel input | AG9: =IF(ISBLANK(S9),S9,I9) -> 0 | AH9: =AH8+B9 -> 170 | AI9: =AH9*$AK$1 -> 106.16202 | AJ9: {=OR(D9=$AT$2:$AT$8)} -> FALSE
A10: BISHOP HILL WF | B10: 40 | C10: COMED | D10: COMED | E10: Onshore Wind | F10: Wind | G10: Wind turbine | K10: Not applicable | L10: Not applicable: no thermal fuel input | M10: =IF(OR(B10="",I10=""),"",B10*I10) | N10: Not applicable – nonthermal | S10: =IF(AND(ISNUMBER(Q10),Q10>0,ISNUMBER(R10),R10>0),R10/Q10,"") | X10: =IF(ISNUMBER(S10),S10,IF(ISNUMBER(I10),I10,"")) | Y10: =IF(ISNUMBER(S10),"2025 EIA-923 plant/group proxy",IF(ISNUMBER(I10),"Technology estimate","No thermal heat rate")) -> No thermal heat rate | Z10: =IF(ISNUMBER(S10),"Review: NOT unit verified",IF(AE10="No match","No EIA match",IF(AF10="Unconfirmed","Unconfirmed EIA candidate",""))) | AE10: N/A (nonthermal) | AF10: No thermal fuel input | AG10: =IF(ISBLANK(S10),S10,I10) -> 0 | AH10: =AH9+B10 -> 210 | AI10: =AH10*$AK$1 -> 131.14132 | AJ10: {=OR(D10=$AT$2:$AT$8)} -> FALSE
A11: BITTER RIDGE WF | B11: 16.9 | C11: AEP | D11: RTO | E11: Onshore Wind | F11: Wind | G11: Wind turbine | K11: Not applicable | L11: Not applicable: no thermal fuel input | M11: =IF(OR(B11="",I11=""),"",B11*I11) | N11: Not applicable – nonthermal | S11: =IF(AND(ISNUMBER(Q11),Q11>0,ISNUMBER(R11),R11>0),R11/Q11,"") | X11: =IF(ISNUMBER(S11),S11,IF(ISNUMBER(I11),I11,"")) | Y11: =IF(ISNUMBER(S11),"2025 EIA-923 plant/group proxy",IF(ISNUMBER(I11),"Technology estimate","No thermal heat rate")) -> No thermal heat rate | Z11: =IF(ISNUMBER(S11),"Review: NOT unit verified",IF(AE11="No match","No EIA match",IF(AF11="Unconfirmed","Unconfirmed EIA candidate",""))) | AE11: N/A (nonthermal) | AF11: No thermal fuel input | AG11: =IF(ISBLANK(S11),S11,I11) -> 0 | AH11: =AH10+B11 -> 226.9 | AI11: =AH11*$AK$1 -> 141.69508 | AJ11: {=OR(D11=$AT$2:$AT$8)} -> FALSE
A12: BLACK ROCK WF | B12: 51.7 | C12: APS | D12: RTO | E12: Onshore Wind | F12: Wind | G12: Wind turbine | K12: Not applicable | L12: Not applicable: no thermal fuel input | M12: =IF(OR(B12="",I12=""),"",B12*I12) | N12: Not applicable – nonthermal | S12: =IF(AND(ISNUMBER(Q12),Q12>0,ISNUMBER(R12),R12>0),R12/Q12,"") | X12: =IF(ISNUMBER(S12),S12,IF(ISNUMBER(I12),I12,"")) | Y12: =IF(ISNUMBER(S12),"2025 EIA-923 plant/group proxy",IF(ISNUMBER(I12),"Technology estimate","No thermal heat rate")) -> No thermal heat rate | Z12: =IF(ISNUMBER(S12),"Review: NOT unit verified",IF(AE12="No match","No EIA match",IF(AF12="Unconfirmed","Unconfirmed EIA candidate",""))) | AE12: N/A (nonthermal) | AF12: No thermal fuel input | AG12: =IF(ISBLANK(S12),S12,I12) -> 0 | AH12: =AH11+B12 -> 278.6 | AI12: =AH12*$AK$1 -> 173.98082 | AJ12: {=OR(D12=$AT$2:$AT$8)} -> FALSE
A13: BLOOMING GROVE WF | B13: 117.5 | C13: COMED | D13: COMED | E13: Onshore Wind | F13: Wind | G13: Wind turbine | K13: Not applicable | L13: Not applicable: no thermal fuel input | M13: =IF(OR(B13="",I13=""),"",B13*I13) | N13: Not applicable – nonthermal | S13: =IF(AND(ISNUMBER(Q13),Q13>0,ISNUMBER(R13),R13>0),R13/Q13,"") | X13: =IF(ISNUMBER(S13),S13,IF(ISNUMBER(I13),I13,"")) | Y13: =IF(ISNUMBER(S13),"2025 EIA-923 plant/group proxy",IF(ISNUMBER(I13),"Technology estimate","No thermal heat rate")) -> No thermal heat rate | Z13: =IF(ISNUMBER(S13),"Review: NOT unit verified",IF(AE13="No match","No EIA match",IF(AF13="Unconfirmed","Unconfirmed EIA candidate",""))) | AE13: N/A (nonthermal) | AF13: No thermal fuel input | AG13: =IF(ISBLANK(S13),S13,I13) -> 0 | AH13: =AH12+B13 -> 396.1 | AI13: =AH13*$AK$1 -> 247.35751 | AJ13: {=OR(D13=$AT$2:$AT$8)} -> FALSE
A14: BLUE CREEK WF | B14: 49.3 | C14: AEP | D14: RTO | E14: Onshore Wind | F14: Wind | G14: Wind turbine | K14: Not applicable | L14: Not applicable: no thermal fuel input | M14: =IF(OR(B14="",I14=""),"",B14*I14) | N14: Not applicable – nonthermal | S14: =IF(AND(ISNUMBER(Q14),Q14>0,ISNUMBER(R14),R14>0),R14/Q14,"") | X14: =IF(ISNUMBER(S14),S14,IF(ISNUMBER(I14),I14,"")) | Y14: =IF(ISNUMBER(S14),"2025 EIA-923 plant/group proxy",IF(ISNUMBER(I14),"Technology estimate","No thermal heat rate")) -> No thermal heat rate | Z14: =IF(ISNUMBER(S14),"Review: NOT unit verified",IF(AE14="No match","No EIA match",IF(AF14="Unconfirmed","Unconfirmed EIA candidate",""))) | AE14: N/A (nonthermal) | AF14: No thermal fuel input | AG14: =IF(ISBLANK(S14),S14,I14) -> 0 | AH14: =AH13+B14 -> 445.4 | AI14: =AH14*$AK$1 -> 278.1445 | AJ14: {=OR(D14=$AT$2:$AT$8)} -> FALSE
A15: BLUFF POINT WF | B15: 24 | C15: AEP | D15: RTO | E15: Onshore Wind | F15: Wind | G15: Wind turbine | K15: Not applicable | L15: Not applicable: no thermal fuel input | M15: =IF(OR(B15="",I15=""),"",B15*I15) | N15: Not applicable – nonthermal | S15: =IF(AND(ISNUMBER(Q15),Q15>0,ISNUMBER(R15),R15>0),R15/Q15,"") | X15: =IF(ISNUMBER(S15),S15,IF(ISNUMBER(I15),I15,"")) | Y15: =IF(ISNUMBER(S15),"2025 EIA-923 plant/group proxy",IF(ISNUMBER(I15),"Technology estimate","No thermal heat rate")) -> No thermal heat rate | Z15: =IF(ISNUMBER(S15),"Review: NOT unit verified",IF(AE15="No match","No EIA match",IF(AF15="Unconfirmed","Unconfirmed EIA candidate",""))) | AE15: N/A (nonthermal) | AF15: No thermal fuel input | AG15: =IF(ISBLANK(S15),S15,I15) -> 0 | AH15: =AH14+B15 -> 469.4 | AI15: =AH15*$AK$1 -> 293.13208 | AJ15: {=OR(D15=$AT$2:$AT$8)} -> FALSE
A16: BRIGHT STALK WF | B16: 94 | C16: COMED | D16: COMED | E16: Onshore Wind | F16: Wind | G16: Wind turbine | K16: Not applicable | L16: Not applicable: no thermal fuel input | M16: =IF(OR(B16="",I16=""),"",B16*I16) | N16: Not applicable – nonthermal | S16: =IF(AND(ISNUMBER(Q16),Q16>0,ISNUMBER(R16),R16>0),R16/Q16,"") | X16: =IF(ISNUMBER(S16),S16,IF(ISNUMBER(I16),I16,"")) | Y16: =IF(ISNUMBER(S16),"2025 EIA-923 plant/group proxy",IF(ISNUMBER(I16),"Technology estimate","No thermal heat rate")) -> No thermal heat rate | Z16: =IF(ISNUMBER(S16),"Review: NOT unit verified",IF(AE16="No match","No EIA match",IF(AF16="Unconfirmed","Unconfirmed EIA candidate",""))) | AE16: N/A (nonthermal) | AF16: No thermal fuel input | AG16: =IF(ISBLANK(S16),S16,I16) -> 0 | AH16: =AH15+B16 -> 563.4 | AI16: =AH16*$AK$1 -> 351.83344 | AJ16: {=OR(D16=$AT$2:$AT$8)} -> FALSE
A17: CAMP GROVE 2 WF | B17: 13 | C17: COMED | D17: COMED | E17: Onshore Wind | F17: Wind | G17: Wind turbine | K17: Not applicable | L17: Not applicable: no thermal fuel input | M17: =IF(OR(B17="",I17=""),"",B17*I17) | N17: Not applicable – nonthermal | S17: =IF(AND(ISNUMBER(Q17),Q17>0,ISNUMBER(R17),R17>0),R17/Q17,"") | X17: =IF(ISNUMBER(S17),S17,IF(ISNUMBER(I17),I17,"")) | Y17: =IF(ISNUMBER(S17),"2025 EIA-923 plant/group proxy",IF(ISNUMBER(I17),"Technology estimate","No thermal heat rate")) -> No thermal heat rate | Z17: =IF(ISNUMBER(S17),"Review: NOT unit verified",IF(AE17="No match","No EIA match",IF(AF17="Unconfirmed","Unconfirmed EIA candidate",""))) | AE17: N/A (nonthermal) | AF17: No thermal fuel input | AG17: =IF(ISBLANK(S17),S17,I17) -> 0 | AH17: =AH16+B17 -> 576.4 | AI17: =AH17*$AK$1 -> 359.95171 | AJ17: {=OR(D17=$AT$2:$AT$8)} -> FALSE
A18: CAMP GROVE WF | B18: 13 | C18: COMED | D18: COMED | E18: Onshore Wind | F18: Wind | G18: Wind turbine | K18: Not applicable | L18: Not applicable: no thermal fuel input | M18: =IF(OR(B18="",I18=""),"",B18*I18) | N18: Not applicable – nonthermal | S18: =IF(AND(ISNUMBER(Q18),Q18>0,ISNUMBER(R18),R18>0),R18/Q18,"") | X18: =IF(ISNUMBER(S18),S18,IF(ISNUMBER(I18),I18,"")) | Y18: =IF(ISNUMBER(S18),"2025 EIA-923 plant/group proxy",IF(ISNUMBER(I18),"Technology estimate","No thermal heat rate")) -> No thermal heat rate | Z18: =IF(ISNUMBER(S18),"Review: NOT unit verified",IF(AE18="No match","No EIA match",IF(AF18="Unconfirmed","Unconfirmed EIA candidate",""))) | AE18: N/A (nonthermal) | AF18: No thermal fuel input | AG18: =IF(ISBLANK(S18),S18,I18) -> 0 | AH18: =AH17+B18 -> 589.4 | AI18: =AH18*$AK$1 -> 368.06998 | AJ18: {=OR(D18=$AT$2:$AT$8)} -> FALSE
A19: CASSELMAN WF | B19: 5.7 | C19: PENELEC | D19: MAAC | E19: Onshore Wind | F19: Wind | G19: Wind turbine | K19: Not applicable | L19: Not applicable: no thermal fuel input | M19: =IF(OR(B19="",I19=""),"",B19*I19) | N19: Not applicable – nonthermal | S19: =IF(AND(ISNUMBER(Q19),Q19>0,ISNUMBER(R19),R19>0),R19/Q19,"") | X19: =IF(ISNUMBER(S19),S19,IF(ISNUMBER(I19),I19,"")) | Y19: =IF(ISNUMBER(S19),"2025 EIA-923 plant/group proxy",IF(ISNUMBER(I19),"Technology estimate","No thermal heat rate")) -> No thermal heat rate | Z19: =IF(ISNUMBER(S19),"Review: NOT unit verified",IF(AE19="No match","No EIA match",IF(AF19="Unconfirmed","Unconfirmed EIA candidate",""))) | AE19: N/A (nonthermal) | AF19: No thermal fuel input | AG19: =IF(ISBLANK(S19),S19,I19) -> 0 | AH19: =AH18+B19 -> 595.1 | AI19: =AH19*$AK$1 -> 371.62953 | AJ19: {=OR(D19=$AT$2:$AT$8)} -> FALSE
A20: CAYUGA RIDGE WF | B20: 45 | C20: COMED | D20: COMED | E20: Onshore Wind | F20: Wind | G20: Wind turbine | K20: Not applicable | L20: Not applicable: no thermal fuel input | M20: =IF(OR(B20="",I20=""),"",B20*I20) | N20: Not applicable – nonthermal | S20: =IF(AND(ISNUMBER(Q20),Q20>0,ISNUMBER(R20),R20>0),R20/Q20,"") | X20: =IF(ISNUMBER(S20),S20,IF(ISNUMBER(I20),I20,"")) | Y20: =IF(ISNUMBER(S20),"2025 EIA-923 plant/group proxy",IF(ISNUMBER(I20),"Technology estimate","No thermal heat rate")) -> No thermal heat rate | Z20: =IF(ISNUMBER(S20),"Review: NOT unit verified",IF(AE20="No match","No EIA match",IF(AF20="Unconfirmed","Unconfirmed EIA candidate",""))) | AE20: N/A (nonthermal) | AF20: No thermal fuel input | AG20: =IF(ISBLANK(S20),S20,I20) -> 0 | AH20: =AH19+B20 -> 640.1 | AI20: =AH20*$AK$1 -> 399.73124 | AJ20: {=OR(D20=$AT$2:$AT$8)} -> FALSE
... A25: DANS MOUNTAIN WF | B25: 25.8 | C25: APS | D25: RTO | E25: Onshore Wind | F25: Wind | G25: Wind turbine | K25: Not applicable | L25: Not applicable: no thermal fuel input | M25: =IF(OR(B25="",I25=""),"",B25*I25) | N25: Not applicable – nonthermal | S25: =IF(AND(ISNUMBER(Q25),Q25>0,ISNUMBER(R25),R25>0),R25/Q25,"") | X25: =IF(ISNUMBER(S25),S25,IF(ISNUMBER(I25),I25,"")) | Y25: =IF(ISNUMBER(S25),"2025 EIA-923 plant/group proxy",IF(ISNUMBER(I25),"Technology estimate","No thermal heat rate")) -> No thermal heat rate | Z25: =IF(ISNUMBER(S25),"Review: NOT unit verified",IF(AE25="No match","No EIA match",IF(AF25="Unconfirmed","Unconfirmed EIA candidate",""))) | AE25: N/A (nonthermal) | AF25: No thermal fuel input | AG25: =IF(ISBLANK(S25),S25,I25) -> 0 | AH25: =AH24+B25 -> 716.9 | AI25: =AH25*$AK$1 -> 447.6915 | AJ25: {=OR(D25=$AT$2:$AT$8)} -> FALSE
A26: DESERT WF | B26: 27 | C26: DOM | D26: DOM | E26: Onshore Wind | F26: Wind | G26: Wind turbine | K26: Not applicable | L26: Not applicable: no thermal fuel input | M26: =IF(OR(B26="",I26=""),"",B26*I26) | N26: Not applicable – nonthermal | S26: =IF(AND(ISNUMBER(Q26),Q26>0,ISNUMBER(R26),R26>0),R26/Q26,"") | X26: =IF(ISNUMBER(S26),S26,IF(ISNUMBER(I26),I26,"")) | Y26: =IF(ISNUMBER(S26),"2025 EIA-923 plant/group proxy",IF(ISNUMBER(I26),"Technology estimate","No thermal heat rate")) -> No thermal heat rate | Z26: =IF(ISNUMBER(S26),"Review: NOT unit verified",IF(AE26="No match","No EIA match",IF(AF26="Unconfirmed","Unconfirmed EIA candidate",""))) | AE26: N/A (nonthermal) | AF26: No thermal fuel input | AG26: =IF(ISBLANK(S26),S26,I26) -> 0 | AH26: =AH25+B26 -> 743.9 | AI26: =AH26*$AK$1 -> 464.55252 | AJ26: {=OR(D26=$AT$2:$AT$8)} -> TRUE | AL26: 23 | AM26: 91962 | AN26: forecasted heat rate | AO26: =_xlfn.XLOOKUP(AM26,AI:AI,AG:AG,,-1) -> 10.7686
A27: EAST CARBONDALE WF | B27: 8.3 | C27: PPL | D27: PPL | E27: Onshore Wind | F27: Wind | G27: Wind turbine | K27: Not applicable | L27: Not applicable: no thermal fuel input | M27: =IF(OR(B27="",I27=""),"",B27*I27) | N27: Not applicable – nonthermal | S27: =IF(AND(ISNUMBER(Q27),Q27>0,ISNUMBER(R27),R27>0),R27/Q27,"") | X27: =IF(ISNUMBER(S27),S27,IF(ISNUMBER(I27),I27,"")) | Y27: =IF(ISNUMBER(S27),"2025 EIA-923 plant/group proxy",IF(ISNUMBER(I27),"Technology estimate","No thermal heat rate")) -> No thermal heat rate | Z27: =IF(ISNUMBER(S27),"Review: NOT unit verified",IF(AE27="No match","No EIA match",IF(AF27="Unconfirmed","Unconfirmed EIA candidate",""))) | AE27: N/A (nonthermal) | AF27: No thermal fuel input | AG27: =IF(ISBLANK(S27),S27,I27) -> 0 | AH27: =AH26+B27 -> 752.2 | AI27: =AH27*$AK$1 -> 469.73573 | AJ27: {=OR(D27=$AT$2:$AT$8)} -> FALSE | AL27: 0 | AM27: 91962 | AP27: RS | AQ27: LKWD CT 1 | AR27: LKWD NuG
A28: ECOGROVE WF | B28: 19.4 | C28: COMED | D28: COMED | E28: Onshore Wind | F28: Wind | G28: Wind turbine | K28: Not applicable | L28: Not applicable: no thermal fuel input | M28: =IF(OR(B28="",I28=""),"",B28*I28) | N28: Not applicable – nonthermal | S28: =IF(AND(ISNUMBER(Q28),Q28>0,ISNUMBER(R28),R28>0),R28/Q28,"") | X28: =IF(ISNUMBER(S28),S28,IF(ISNUMBER(I28),I28,"")) | Y28: =IF(ISNUMBER(S28),"2025 EIA-923 plant/group proxy",IF(ISNUMBER(I28),"Technology estimate","No thermal heat rate")) -> No thermal heat rate | Z28: =IF(ISNUMBER(S28),"Review: NOT unit verified",IF(AE28="No match","No EIA match",IF(AF28="Unconfirmed","Unconfirmed EIA candidate",""))) | AE28: N/A (nonthermal) | AF28: No thermal fuel input | AG28: =IF(ISBLANK(S28),S28,I28) -> 0 | AH28: =AH27+B28 -> 771.6 | AI28: =AH28*$AK$1 -> 481.85069 | AJ28: {=OR(D28=$AT$2:$AT$8)} -> FALSE | AK28: 46317 | AL28: HE 1 | AM28: 77671 | AN28: =_xlfn.XLOOKUP(AM28,$AI:$AI,$AG:$AG,,-1) -> 10.1627 | AP28: =$AT$28 -> 10.5628 | AQ28: =$AT$29 -> 10.5 | AR28: =$AT$30 -> 7.4 | AS28: Rock Springs CT1 | AT28: =_xlfn.XLOOKUP(AS28,$A:$A,$AG:$AG,,-1) -> 10.5628
A29: FIELD MOUNTAIN WF | B29: 14.1 | C29: APS | D29: RTO | E29: Onshore Wind | F29: Wind | G29: Wind turbine | K29: Not applicable | L29: Not applicable: no thermal fuel input | M29: =IF(OR(B29="",I29=""),"",B29*I29) | N29: Not applicable – nonthermal | S29: =IF(AND(ISNUMBER(Q29),Q29>0,ISNUMBER(R29),R29>0),R29/Q29,"") | X29: =IF(ISNUMBER(S29),S29,IF(ISNUMBER(I29),I29,"")) | Y29: =IF(ISNUMBER(S29),"2025 EIA-923 plant/group proxy",IF(ISNUMBER(I29),"Technology estimate","No thermal heat rate")) -> No thermal heat rate | Z29: =IF(ISNUMBER(S29),"Review: NOT unit verified",IF(AE29="No match","No EIA match",IF(AF29="Unconfirmed","Unconfirmed EIA candidate",""))) | AE29: N/A (nonthermal) | AF29: No thermal fuel input | AG29: =IF(ISBLANK(S29),S29,I29) -> 0 | AH29: =AH28+B29 -> 785.7 | AI29: =AH29*$AK$1 -> 490.65589 | AJ29: {=OR(D29=$AT$2:$AT$8)} -> FALSE | AL29: HE 2 | AM29: 75828 | AN29: =_xlfn.XLOOKUP(AM29,$AI:$AI,$AG:$AG,,-1) -> 9.9859 | AP29: =$AT$28 -> 10.5628 | AQ29: =$AT$29 -> 10.5 | AR29: =$AT$30 -> 7.4 | AS29: Lakewood CT1 | AT29: =_xlfn.XLOOKUP(AS29,$A:$A,$AG:$AG,,-1) -> 10.5
A30: FORWARD WF | B30: 10 | C30: PENELEC | D30: MAAC | E30: Onshore Wind | F30: Wind | G30: Wind turbine | K30: Not applicable | L30: Not applicable: no thermal fuel input | M30: =IF(OR(B30="",I30=""),"",B30*I30) | N30: Not applicable – nonthermal | S30: =IF(AND(ISNUMBER(Q30),Q30>0,ISNUMBER(R30),R30>0),R30/Q30,"") | X30: =IF(ISNUMBER(S30),S30,IF(ISNUMBER(I30),I30,"")) | Y30: =IF(ISNUMBER(S30),"2025 EIA-923 plant/group proxy",IF(ISNUMBER(I30),"Technology estimate","No thermal heat rate")) -> No thermal heat rate | Z30: =IF(ISNUMBER(S30),"Review: NOT unit verified",IF(AE30="No match","No EIA match",IF(AF30="Unconfirmed","Unconfirmed EIA candidate",""))) | AE30: N/A (nonthermal) | AF30: No thermal fuel input | AG30: =IF(ISBLANK(S30),S30,I30) -> 0 | AH30: =AH29+B30 -> 795.7 | AI30: =AH30*$AK$1 -> 496.90072 | AJ30: {=OR(D30=$AT$2:$AT$8)} -> FALSE | AL30: HE 3 | AM30: 74857 | AN30: =_xlfn.XLOOKUP(AM30,$AI:$AI,$AG:$AG,,-1) -> 9.9708 | AP30: =$AT$28 -> 10.5628 | AQ30: =$AT$29 -> 10.5 | AR30: =$AT$30 -> 7.4 | AS30: Lakewood NUG | AT30: =_xlfn.XLOOKUP(AS30,$A:$A,$AG:$AG,,-1) -> 7.4
A31: FOUR MILE RIDGE WF | B31: 5.2 | C31: APS | D31: RTO | E31: Onshore Wind | F31: Wind | G31: Wind turbine | K31: Not applicable | L31: Not applicable: no thermal fuel input | M31: =IF(OR(B31="",I31=""),"",B31*I31) | N31: Not applicable – nonthermal | S31: =IF(AND(ISNUMBER(Q31),Q31>0,ISNUMBER(R31),R31>0),R31/Q31,"") | X31: =IF(ISNUMBER(S31),S31,IF(ISNUMBER(I31),I31,"")) | Y31: =IF(ISNUMBER(S31),"2025 EIA-923 plant/group proxy",IF(ISNUMBER(I31),"Technology estimate","No thermal heat rate")) -> No thermal heat rate | Z31: =IF(ISNUMBER(S31),"Review: NOT unit verified",IF(AE31="No match","No EIA match",IF(AF31="Unconfirmed","Unconfirmed EIA candidate",""))) | AE31: N/A (nonthermal) | AF31: No thermal fuel input | AG31: =IF(ISBLANK(S31),S31,I31) -> 0 | AH31: =AH30+B31 -> 800.9 | AI31: =AH31*$AK$1 -> 500.14803 | AJ31: {=OR(D31=$AT$2:$AT$8)} -> FALSE | AL31: HE 4 | AM31: 74756 | AN31: =_xlfn.XLOOKUP(AM31,$AI:$AI,$AG:$AG,,-1) -> 9.9708 | AP31: =$AT$28 -> 10.5628 | AQ31: =$AT$29 -> 10.5 | AR31: =$AT$30 -> 7.4
A32: FOWLER RIDGE 2 WF | B32: 26 | C32: AEP | D32: RTO | E32: Onshore Wind | F32: Wind | G32: Wind turbine | K32: Not applicable | L32: Not applicable: no thermal fuel input | M32: =IF(OR(B32="",I32=""),"",B32*I32) | N32: Not applicable – nonthermal | S32: =IF(AND(ISNUMBER(Q32),Q32>0,ISNUMBER(R32),R32>0),R32/Q32,"") | X32: =IF(ISNUMBER(S32),S32,IF(ISNUMBER(I32),I32,"")) | Y32: =IF(ISNUMBER(S32),"2025 EIA-923 plant/group proxy",IF(ISNUMBER(I32),"Technology estimate","No thermal heat rate")) -> No thermal heat rate | Z32: =IF(ISNUMBER(S32),"Review: NOT unit verified",IF(AE32="No match","No EIA match",IF(AF32="Unconfirmed","Unconfirmed EIA candidate",""))) | AE32: N/A (nonthermal) | AF32: No thermal fuel input | AG32: =IF(ISBLANK(S32),S32,I32) -> 0 | AH32: =AH31+B32 -> 826.9 | AI32: =AH32*$AK$1 -> 516.38457 | AJ32: {=OR(D32=$AT$2:$AT$8)} -> FALSE | AL32: HE 5 | AM32: 76041 | AN32: =_xlfn.XLOOKUP(AM32,$AI:$AI,$AG:$AG,,-1) -> 10.0705 | AP32: =$AT$28 -> 10.5628 | AQ32: =$AT$29 -> 10.5 | AR32: =$AT$30 -> 7.4
A33: FOWLER RIDGE 3 WF | B33: 12.5 | C33: AEP | D33: RTO | E33: Onshore Wind | F33: Wind | G33: Wind turbine | K33: Not applicable | L33: Not applicable: no thermal fuel input | M33: =IF(OR(B33="",I33=""),"",B33*I33) | N33: Not applicable – nonthermal | S33: =IF(AND(ISNUMBER(Q33),Q33>0,ISNUMBER(R33),R33>0),R33/Q33,"") | X33: =IF(ISNUMBER(S33),S33,IF(ISNUMBER(I33),I33,"")) | Y33: =IF(ISNUMBER(S33),"2025 EIA-923 plant/group proxy",IF(ISNUMBER(I33),"Technology estimate","No thermal heat rate")) -> No thermal heat rate | Z33: =IF(ISNUMBER(S33),"Review: NOT unit verified",IF(AE33="No match","No EIA match",IF(AF33="Unconfirmed","Unconfirmed EIA candidate",""))) | AE33: N/A (nonthermal) | AF33: No thermal fuel input | AG33: =IF(ISBLANK(S33),S33,I33) -> 0 | AH33: =AH32+B33 -> 839.4 | AI33: =AH33*$AK$1 -> 524.1906 | AJ33: {=OR(D33=$AT$2:$AT$8)} -> FALSE | AL33: HE 6 | AM33: 79787 | AN33: =_xlfn.XLOOKUP(AM33,$AI:$AI,$AG:$AG,,-1) -> 10.2551 | AP33: =$AT$28 -> 10.5628 | AQ33: =$AT$29 -> 10.5 | AR33: =$AT$30 -> 7.4
A34: FOWLER RIDGE 4 WF | B34: 26.8 | C34: AEP | D34: RTO | E34: Onshore Wind | F34: Wind | G34: Wind turbine | K34: Not applicable | L34: Not applicable: no thermal fuel input | M34: =IF(OR(B34="",I34=""),"",B34*I34) | N34: Not applicable – nonthermal | S34: =IF(AND(ISNUMBER(Q34),Q34>0,ISNUMBER(R34),R34>0),R34/Q34,"") | X34: =IF(ISNUMBER(S34),S34,IF(ISNUMBER(I34),I34,"")) | Y34: =IF(ISNUMBER(S34),"2025 EIA-923 plant/group proxy",IF(ISNUMBER(I34),"Technology estimate","No thermal heat rate")) -> No thermal heat rate | Z34: =IF(ISNUMBER(S34),"Review: NOT unit verified",IF(AE34="No match","No EIA match",IF(AF34="Unconfirmed","Unconfirmed EIA candidate",""))) | AE34: N/A (nonthermal) | AF34: No thermal fuel input | AG34: =IF(ISBLANK(S34),S34,I34) -> 0 | AH34: =AH33+B34 -> 866.2 | AI34: =AH34*$AK$1 -> 540.92673 | AJ34: {=OR(D34=$AT$2:$AT$8)} -> FALSE | AL34: HE 7 | AM34: 85947 | AN34: =_xlfn.XLOOKUP(AM34,$AI:$AI,$AG:$AG,,-1) -> 10.4275 | AP34: =$AT$28 -> 10.5628 | AQ34: =$AT$29 -> 10.5 | AR34: =$AT$30 -> 7.4
A35: FOWLER RIDGE WF | B35: 37 | C35: AEP | D35: RTO | E35: Onshore Wind | F35: Wind | G35: Wind turbine | K35: Not applicable | L35: Not applicable: no thermal fuel input | M35: =IF(OR(B35="",I35=""),"",B35*I35) | N35: Not applicable – nonthermal | S35: =IF(AND(ISNUMBER(Q35),Q35>0,ISNUMBER(R35),R35>0),R35/Q35,"") | X35: =IF(ISNUMBER(S35),S35,IF(ISNUMBER(I35),I35,"")) | Y35: =IF(ISNUMBER(S35),"2025 EIA-923 plant/group proxy",IF(ISNUMBER(I35),"Technology estimate","No thermal heat rate")) -> No thermal heat rate | Z35: =IF(ISNUMBER(S35),"Review: NOT unit verified",IF(AE35="No match","No EIA match",IF(AF35="Unconfirmed","Unconfirmed EIA candidate",""))) | AE35: N/A (nonthermal) | AF35: No thermal fuel input | AG35: =IF(ISBLANK(S35),S35,I35) -> 0 | AH35: =AH34+B35 -> 903.2 | AI35: =AH35*$AK$1 -> 564.03259 | AJ35: {=OR(D35=$AT$2:$AT$8)} -> FALSE | AL35: HE 8 | AM35: 90182 | AN35: =_xlfn.XLOOKUP(AM35,$AI:$AI,$AG:$AG,,-1) -> 10.6032 | AP35: =$AT$28 -> 10.5628 | AQ35: =$AT$29 -> 10.5 | AR35: =$AT$30 -> 7.4
A36: GRAND RIDGE 2 WF | B36: 19.7 | C36: COMED | D36: COMED | E36: Onshore Wind | F36: Wind | G36: Wind turbine | K36: Not applicable | L36: Not applicable: no thermal fuel input | M36: =IF(OR(B36="",I36=""),"",B36*I36) | N36: Not applicable – nonthermal | S36: =IF(AND(ISNUMBER(Q36),Q36>0,ISNUMBER(R36),R36>0),R36/Q36,"") | X36: =IF(ISNUMBER(S36),S36,IF(ISNUMBER(I36),I36,"")) | Y36: =IF(ISNUMBER(S36),"2025 EIA-923 plant/group proxy",IF(ISNUMBER(I36),"Technology estimate","No thermal heat rate")) -> No thermal heat rate | Z36: =IF(ISNUMBER(S36),"Review: NOT unit verified",IF(AE36="No match","No EIA match",IF(AF36="Unconfirmed","Unconfirmed EIA candidate",""))) | AE36: N/A (nonthermal) | AF36: No thermal fuel input | AG36: =IF(ISBLANK(S36),S36,I36) -> 0 | AH36: =AH35+B36 -> 922.9 | AI36: =AH36*$AK$1 -> 576.33489 | AJ36: {=OR(D36=$AT$2:$AT$8)} -> FALSE | AL36: HE 9 | AM36: 90430 | AN36: =_xlfn.XLOOKUP(AM36,$AI:$AI,$AG:$AG,,-1) -> 10.6381 | AP36: =$AT$28 -> 10.5628 | AQ36: =$AT$29 -> 10.5 | AR36: =$AT$30 -> 7.4
A37: GRAND RIDGE 3 WF | B37: 13.3 | C37: COMED | D37: COMED | E37: Onshore Wind | F37: Wind | G37: Wind turbine | K37: Not applicable | L37: Not applicable: no thermal fuel input | M37: =IF(OR(B37="",I37=""),"",B37*I37) | N37: Not applicable – nonthermal | S37: =IF(AND(ISNUMBER(Q37),Q37>0,ISNUMBER(R37),R37>0),R37/Q37,"") | X37: =IF(ISNUMBER(S37),S37,IF(ISNUMBER(I37),I37,"")) | Y37: =IF(ISNUMBER(S37),"2025 EIA-923 plant/group proxy",IF(ISNUMBER(I37),"Technology estimate","No thermal heat rate")) -> No thermal heat rate | Z37: =IF(ISNUMBER(S37),"Review: NOT unit verified",IF(AE37="No match","No EIA match",IF(AF37="Unconfirmed","Unconfirmed EIA candidate",""))) | AE37: N/A (nonthermal) | AF37: No thermal fuel input | AG37: =IF(ISBLANK(S37),S37,I37) -> 0 | AH37: =AH36+B37 -> 936.2 | AI37: =AH37*$AK$1 -> 584.64051 | AJ37: {=OR(D37=$AT$2:$AT$8)} -> FALSE | AL37: HE 10 | AM37: 88805 | AN37: =_xlfn.XLOOKUP(AM37,$AI:$AI,$AG:$AG,,-1) -> 10.5278 | AP37: =$AT$28 -> 10.5628 | AQ37: =$AT$29 -> 10.5 | AR37: =$AT$30 -> 7.4
A38: GRAND RIDGE 4 WF | B38: 2.8 | C38: COMED | D38: COMED | E38: Onshore Wind | F38: Wind | G38: Wind turbine | K38: Not applicable | L38: Not applicable: no thermal fuel input | M38: =IF(OR(B38="",I38=""),"",B38*I38) | N38: Not applicable – nonthermal | S38: =IF(AND(ISNUMBER(Q38),Q38>0,ISNUMBER(R38),R38>0),R38/Q38,"") | X38: =IF(ISNUMBER(S38),S38,IF(ISNUMBER(I38),I38,"")) | Y38: =IF(ISNUMBER(S38),"2025 EIA-923 plant/group proxy",IF(ISNUMBER(I38),"Technology estimate","No thermal heat rate")) -> No thermal heat rate | Z38: =IF(ISNUMBER(S38),"Review: NOT unit verified",IF(AE38="No match","No EIA match",IF(AF38="Unconfirmed","Unconfirmed EIA candidate",""))) | AE38: N/A (nonthermal) | AF38: No thermal fuel input | AG38: =IF(ISBLANK(S38),S38,I38) -> 0 | AH38: =AH37+B38 -> 939 | AI38: =AH38*$AK$1 -> 586.38906 | AJ38: {=OR(D38=$AT$2:$AT$8)} -> FALSE | AL38: HE 11 | AM38: 87252 | AN38: =_xlfn.XLOOKUP(AM38,$AI:$AI,$AG:$AG,,-1) -> 10.5 | AP38: =$AT$28 -> 10.5628 | AQ38: =$AT$29 -> 10.5 | AR38: =$AT$30 -> 7.4
A39: GRAND RIDGE WF | B39: 38.2 | C39: COMED | D39: COMED | E39: Onshore Wind | F39: Wind | G39: Wind turbine | K39: Not applicable | L39: Not applicable: no thermal fuel input | M39: =IF(OR(B39="",I39=""),"",B39*I39) | N39: Not applicable – nonthermal | S39: =IF(AND(ISNUMBER(Q39),Q39>0,ISNUMBER(R39),R39>0),R39/Q39,"") | X39: =IF(ISNUMBER(S39),S39,IF(ISNUMBER(I39),I39,"")) | Y39: =IF(ISNUMBER(S39),"2025 EIA-923 plant/group proxy",IF(ISNUMBER(I39),"Technology estimate","No thermal heat rate")) -> No thermal heat rate | Z39: =IF(ISNUMBER(S39),"Review: NOT unit verified",IF(AE39="No match","No EIA match",IF(AF39="Unconfirmed","Unconfirmed EIA candidate",""))) | AE39: N/A (nonthermal) | AF39: No thermal fuel input | AG39: =IF(ISBLANK(S39),S39,I39) -> 0 | AH39: =AH38+B39 -> 977.2 | AI39: =AH39*$AK$1 -> 610.24429 | AJ39: {=OR(D39=$AT$2:$AT$8)} -> FALSE | AL39: HE 12 | AM39: 86068 | AN39: =_xlfn.XLOOKUP(AM39,$AI:$AI,$AG:$AG,,-1) -> 10.4823 | AP39: =$AT$28 -> 10.5628 | AQ39: =$AT$29 -> 10.5 | AR39: =$AT$30 -> 7.4
A40: GREEN RIVER WF | B40: 85 | C40: COMED | D40: COMED | E40: Onshore Wind | F40: Wind | G40: Wind turbine | K40: Not applicable | L40: Not applicable: no thermal fuel input | M40: =IF(OR(B40="",I40=""),"",B40*I40) | N40: Not applicable – nonthermal | S40: =IF(AND(ISNUMBER(Q40),Q40>0,ISNUMBER(R40),R40>0),R40/Q40,"") | X40: =IF(ISNUMBER(S40),S40,IF(ISNUMBER(I40),I40,"")) | Y40: =IF(ISNUMBER(S40),"2025 EIA-923 plant/group proxy",IF(ISNUMBER(I40),"Technology estimate","No thermal heat rate")) -> No thermal heat rate | Z40: =IF(ISNUMBER(S40),"Review: NOT unit verified",IF(AE40="No match","No EIA match",IF(AF40="Unconfirmed","Unconfirmed EIA candidate",""))) | AE40: N/A (nonthermal) | AF40: No thermal fuel input | AG40: =IF(ISBLANK(S40),S40,I40) -> 0 | AH40: =AH39+B40 -> 1062.2 | AI40: =AH40*$AK$1 -> 663.3253 | AJ40: {=OR(D40=$AT$2:$AT$8)} -> FALSE | AL40: HE 13 | AM40: 85257 | AN40: =_xlfn.XLOOKUP(AM40,$AI:$AI,$AG:$AG,,-1) -> 10.3833 | AP40: =$AT$28 -> 10.5628 | AQ40: =$AT$29 -> 10.5 | AR40: =$AT$30 -> 7.4
A41: GREENLAND GAP WF | B41: 141 | C41: APS | D41: RTO | E41: Onshore Wind | F41: Wind | G41: Wind turbine | K41: Not applicable | L41: Not applicable: no thermal fuel input | M41: =IF(OR(B41="",I41=""),"",B41*I41) | N41: Not applicable – nonthermal | S41: =IF(AND(ISNUMBER(Q41),Q41>0,ISNUMBER(R41),R41>0),R41/Q41,"") | X41: =IF(ISNUMBER(S41),S41,IF(ISNUMBER(I41),I41,"")) | Y41: =IF(ISNUMBER(S41),"2025 EIA-923 plant/group proxy",IF(ISNUMBER(I41),"Technology estimate","No thermal heat rate")) -> No thermal heat rate | Z41: =IF(ISNUMBER(S41),"Review: NOT unit verified",IF(AE41="No match","No EIA match",IF(AF41="Unconfirmed","Unconfirmed EIA candidate",""))) | AE41: N/A (nonthermal) | AF41: No thermal fuel input | AG41: =IF(ISBLANK(S41),S41,I41) -> 0 | AH41: =AH40+B41 -> 1203.2 | AI41: =AH41*$AK$1 -> 751.37733 | AJ41: {=OR(D41=$AT$2:$AT$8)} -> FALSE | AL41: HE 14 | AM41: 84932 | AN41: =_xlfn.XLOOKUP(AM41,$AI:$AI,$AG:$AG,,-1) -> 10.3833 | AP41: =$AT$28 -> 10.5628 | AQ41: =$AT$29 -> 10.5 | AR41: =$AT$30 -> 7.4
A42: HAVILAND WF | B42: 13 | C42: AEP | D42: RTO | E42: Onshore Wind | F42: Wind | G42: Wind turbine | K42: Not applicable | L42: Not applicable: no thermal fuel input | M42: =IF(OR(B42="",I42=""),"",B42*I42) | N42: Not applicable – nonthermal | S42: =IF(AND(ISNUMBER(Q42),Q42>0,ISNUMBER(R42),R42>0),R42/Q42,"") | X42: =IF(ISNUMBER(S42),S42,IF(ISNUMBER(I42),I42,"")) | Y42: =IF(ISNUMBER(S42),"2025 EIA-923 plant/group proxy",IF(ISNUMBER(I42),"Technology estimate","No thermal heat rate")) -> No thermal heat rate | Z42: =IF(ISNUMBER(S42),"Review: NOT unit verified",IF(AE42="No match","No EIA match",IF(AF42="Unconfirmed","Unconfirmed EIA candidate",""))) | AE42: N/A (nonthermal) | AF42: No thermal fuel input | AG42: =IF(ISBLANK(S42),S42,I42) -> 0 | AH42: =AH41+B42 -> 1216.2 | AI42: =AH42*$AK$1 -> 759.4956 | AJ42: {=OR(D42=$AT$2:$AT$8)} -> FALSE | AL42: HE 15 | AM42: 84726 | AN42: =_xlfn.XLOOKUP(AM42,$AI:$AI,$AG:$AG,,-1) -> 10.3833 | AP42: =$AT$28 -> 10.5628 | AQ42: =$AT$29 -> 10.5 | AR42: =$AT$30 -> 7.4
... A51: LOCUST RIDGE 2 WF | B51: 10.3 | C51: PPL | D51: PPL | E51: Onshore Wind | F51: Wind | G51: Wind turbine | K51: Not applicable | L51: Not applicable: no thermal fuel input | M51: =IF(OR(B51="",I51=""),"",B51*I51) | N51: Not applicable – nonthermal | S51: =IF(AND(ISNUMBER(Q51),Q51>0,ISNUMBER(R51),R51>0),R51/Q51,"") | X51: =IF(ISNUMBER(S51),S51,IF(ISNUMBER(I51),I51,"")) | Y51: =IF(ISNUMBER(S51),"2025 EIA-923 plant/group proxy",IF(ISNUMBER(I51),"Technology estimate","No thermal heat rate")) -> No thermal heat rate | Z51: =IF(ISNUMBER(S51),"Review: NOT unit verified",IF(AE51="No match","No EIA match",IF(AF51="Unconfirmed","Unconfirmed EIA candidate",""))) | AE51: N/A (nonthermal) | AF51: No thermal fuel input | AG51: =IF(ISBLANK(S51),S51,I51) -> 0 | AH51: =AH50+B51 -> 1655.8 | AI51: =AH51*$AK$1 -> 1034.0181 | AJ51: {=OR(D51=$AT$2:$AT$8)} -> FALSE | AL51: HE 24 | AM51: 80370 | AN51: =_xlfn.XLOOKUP(AM51,$AI:$AI,$AG:$AG,,-1) -> 10.2551 | AP51: =$AT$28 -> 10.5628 | AQ51: =$AT$29 -> 10.5 | AR51: =$AT$30 -> 7.4
A52: LOCUST RIDGE WF | B52: 3 | C52: PPL | D52: PPL | E52: Onshore Wind | F52: Wind | G52: Wind turbine | K52: Not applicable | L52: Not applicable: no thermal fuel input | M52: =IF(OR(B52="",I52=""),"",B52*I52) | N52: Not applicable – nonthermal | S52: =IF(AND(ISNUMBER(Q52),Q52>0,ISNUMBER(R52),R52>0),R52/Q52,"") | X52: =IF(ISNUMBER(S52),S52,IF(ISNUMBER(I52),I52,"")) | Y52: =IF(ISNUMBER(S52),"2025 EIA-923 plant/group proxy",IF(ISNUMBER(I52),"Technology estimate","No thermal heat rate")) -> No thermal heat rate | Z52: =IF(ISNUMBER(S52),"Review: NOT unit verified",IF(AE52="No match","No EIA match",IF(AF52="Unconfirmed","Unconfirmed EIA candidate",""))) | AE52: N/A (nonthermal) | AF52: No thermal fuel input | AG52: =IF(ISBLANK(S52),S52,I52) -> 0 | AH52: =AH51+B52 -> 1658.8 | AI52: =AH52*$AK$1 -> 1035.8916 | AJ52: {=OR(D52=$AT$2:$AT$8)} -> FALSE
...

Sheet Class Assumptions
A1: PJM Class | B1: Assumed Fuel | C1: Technology | D1: Low HR | E1: Base HR | F1: High HR | G1: Notes
A2: 10-hr Storage | B2: Electricity | C2: Battery/storage | G2: Not applicable: use round-trip efficiency instead
A3: 4-hr Storage | B3: Electricity | C3: Battery/storage | G3: Not applicable: use round-trip efficiency instead
A4: 6-hr Storage | B4: Electricity | C4: Battery/storage | G4: Not applicable: use round-trip efficiency instead
A5: 8-hr Storage | B5: Electricity | C5: Battery/storage | G5: Not applicable: use round-trip efficiency instead
A6: Coal | B6: Coal | C6: Coal steam | D6: 9 | E6: 10.3 | F6: 12 | G6: Representative full-load net HHV
A7: Diesel Utility | B7: Distillate diesel (assumed) | C7: Diesel engine / oil-fired | D7: 8 | E7: 9.5 | F7: 12 | G7: Technology may vary; verify fuel and engine type
A8: Gas Combined Cycle | B8: Natural gas | C8: Combined cycle | D8: 6.5 | E8: 7.2 | F8: 8.2 | G8: Representative full-load net HHV
A9: Gas Combined Cycle Dual | B9: Natural gas (assumed) | C9: Combined cycle dual fuel | D9: 6.6 | E9: 7.4 | F9: 8.5 | G9: Gas firing assumed; oil operation may differ
A10: Gas Combustion Turbine | B10: Natural gas | C10: Simple-cycle turbine | D10: 9 | E10: 10.5 | F10: 13 | G10: Representative full-load net HHV
A11: Gas Combustion Turbine Dual | B11: Natural gas (assumed) | C11: Simple-cycle dual fuel | D11: 9.2 | E11: 10.8 | F11: 13.5 | G11: Gas firing assumed; oil operation may differ
A12: Hybrid CL - Solar Tracking | B12: Solar / hybrid | C12: Hybrid solar | G12: Not applicable to solar portion; verify hybrid components
A13: Hydro Intermittent | B13: Hydro | C13: Hydroelectric | G13: Not applicable: no thermal fuel input
A14: HydroNPS | B14: Hydro | C14: Hydroelectric | G14: Not applicable: no thermal fuel input
A15: Landfill Intermittent | B15: Landfill gas (assumed) | C15: Landfill gas | D15: 9 | E15: 12 | F15: 16 | G15: High uncertainty; may be reciprocating engine or turbine
A16: Nuclear | B16: Nuclear heat | C16: Nuclear steam | D16: 10 | E16: 10.5 | F16: 11.2 | G16: Thermal equivalent only; not a fossil-fuel cost heat rate
A17: Offshore Wind | B17: Wind | C17: Wind turbine | G17: Not applicable: no thermal fuel input
A18: Onshore Wind | B18: Wind | C18: Wind turbine | G18: Not applicable: no thermal fuel input
A19: Other | B19: Unknown | C19: Other / unspecified | G19: Insufficient technology and fuel information
A20: Other Unlimited Resource | B20: Unknown | C20: Other / unspecified | G20: Insufficient technology and fuel information
A21: Solar Fixed | B21: Solar | C21: Solar PV | G21: Not applicable: no thermal fuel input
A22: Solar Tracking | B22: Solar | C22: Solar PV | G22: Not applicable: no thermal fuel input
A23: Steam | B23: Unknown | C23: Unspecified steam | G23: Cannot infer fuel from class; requires plant-level mapping

Sheet Methodology
A1: Purpose | B1: Indicative resource-level full-load heat-rate estimates, not actual unit measurements.
A2: Input | B2: PJM 2026/2027 Existing Resource List, as of 2025-10-14 (user supplied).
A3: Basis | B3: MMBtu fuel energy per MWh electric generation; representative net HHV assumptions.
A4: Limitation | B4: PJM CLASSTYPE does not identify specific turbine model, vintage, fuel or dispatch load.
A5: Ranges | B5: Illustrative engineering screening assumptions, not PJM/EIA verified plant heat rates.
A6: Nuclear | B6: Thermal equivalent only; do not use to infer market fuel cost.
A7: Solar/wind/hydro/storage | B7: No thermal fuel heat rate. Storage should be modeled with efficiency.
A8: Steam/Other | B8: Not estimated because fuel and technology are not identifiable from source class.
A9: Dual fuel | B9: Natural-gas operation assumed; alternate fuel could have different characteristics.
A10: Partial load | B10: Heat rate often rises at low loading; base estimate represents approximate full-load performance.
A11: ICAP multiplication | B11: Thermal input at ICAP is hypothetical, not an actual output or availability forecast.
A12: External methodology reference | B12: https://www.eia.gov/electricity/annual/html/epa_08_01.html
... A39: 2025 reported formula | B39: EIA-923 Page 1 monthly Elec_MMBtu / Netgen; in workbook cells R/Q and in EIA Group Data F/G.

Sheet EIA Matching Review
A1: PJM Resource | B1: PJM Class | C1: Candidate Rank | D1: EIA Plant ID | E1: EIA Plant Name | F1: State | G1: Name Fit | H1: Overall Score | I1: EIA-860 Technology Match | J1: 2025 Data Present | K1: 2025 Net MWh | L1: 2025 Fuel for Electric MMBtu | M1: 2025 Group Heat Rate | N1: Fuel / Prime Movers | O1: EIA-860 Generator IDs | P1: EIA-860 Operable MW | Q1: Decision | R1: 2025 EIA-923 Source | S1: EIA-860 Source | T1: OUTPUT
A2: UNIVERSITY PARK NORTH CT10 | B2: Gas Combustion Turbine | C2: 2 | D2: 55250 | E2: University Park South | F2: IL | G2: 0.5599 | H2: 0.6059 | I2: Yes | J2: No / invalid | K2: 151438 | L2: 1725 | M2: 0.0114 | N2: GT/NG | O2: UPG1, UPG2, UPG3, UPG4, UPG5, UPG6 | P2: 300 | Q2: Candidate only – do not treat as matched | R2: https://www.eia.gov/electricity/data/eia923/ | S2: https://www.eia.gov/electricity/data/eia860/ | T2: =P2 -> 300
A3: UNIVERSITY PARK NORTH CT11 | B3: Gas Combustion Turbine | C3: 2 | D3: 55250 | E3: University Park South | F3: IL | G3: 0.5599 | H3: 0.6059 | I3: Yes | J3: No / invalid | K3: 151438 | L3: 1725 | M3: 0.0114 | N3: GT/NG | O3: UPG1, UPG2, UPG3, UPG4, UPG5, UPG6 | P3: 300 | Q3: Candidate only – do not treat as matched | R3: https://www.eia.gov/electricity/data/eia923/ | S3: https://www.eia.gov/electricity/data/eia860/ | T3: =T2+P3 -> 600
A4: UNIVERSITY PARK NORTH CT12 | B4: Gas Combustion Turbine | C4: 2 | D4: 55250 | E4: University Park South | F4: IL | G4: 0.5599 | H4: 0.6059 | I4: Yes | J4: No / invalid | K4: 151438 | L4: 1725 | M4: 0.0114 | N4: GT/NG | O4: UPG1, UPG2, UPG3, UPG4, UPG5, UPG6 | P4: 300 | Q4: Candidate only – do not treat as matched | R4: https://www.eia.gov/electricity/data/eia923/ | S4: https://www.eia.gov/electricity/data/eia860/ | T4: =T3+P4 -> 900
A5: COCHRAN MILL | B5: Gas Combined Cycle | C5: 1 | D5: 54096 | E5: International Paper Riverdale Mill | F5: AL | G5: 0.4123 | H5: 0.3403 | I5: Yes | J5: No / invalid | K5: 324666.87 | L5: 1099323 | M5: 3.386 | N5: CA/NG, CT/NG | O5: GEN3, GEN4 | P5: 55.2 | Q5: Candidate only – do not treat as matched | R5: https://www.eia.gov/electricity/data/eia923/ | S5: https://www.eia.gov/electricity/data/eia860/ | T5: =T4+P5 -> 955.2
A6: FORD MILL 1 ST | B6: Gas Combined Cycle | C6: 1 | D6: 54096 | E6: International Paper Riverdale Mill | F6: AL | G6: 0.4077 | H6: 0.3357 | I6: Yes | J6: No / invalid | K6: 324666.87 | L6: 1099323 | M6: 3.386 | N6: CA/NG, CT/NG | O6: GEN3, GEN4 | P6: 55.2 | Q6: Candidate only – do not treat as matched | R6: https://www.eia.gov/electricity/data/eia923/ | S6: https://www.eia.gov/electricity/data/eia860/ | T6: =T5+P6 -> 1010.4
A7: FORD MILL 2 ST | B7: Gas Combined Cycle | C7: 1 | D7: 54096 | E7: International Paper Riverdale Mill | F7: AL | G7: 0.4077 | H7: 0.3357 | I7: Yes | J7: No / invalid | K7: 324666.87 | L7: 1099323 | M7: 3.386 | N7: CA/NG, CT/NG | O7: GEN3, GEN4 | P7: 55.2 | Q7: Candidate only – do not treat as matched | R7: https://www.eia.gov/electricity/data/eia923/ | S7: https://www.eia.gov/electricity/data/eia860/ | T7: =T6+P7 -> 1065.6
A8: OREGON CC | B8: Gas Combined Cycle | C8: 3 | D8: 57653 | E8: Oregon State University Energy Center | F8: OR | G8: 0.7225 | H8: 0.6225 | I8: No | J8: No / invalid | K8: 33285 | L8: 146048 | M8: 4.3878 | N8: CT/NG | P8: 0 | Q8: Candidate only – do not treat as matched | R8: https://www.eia.gov/electricity/data/eia923/ | S8: https://www.eia.gov/electricity/data/eia860/ | T8: =T7+P8 -> 1065.6
A9: WASHINGTON 1 | B9: Gas Combined Cycle | C9: 3 | D9: 7697 | E9: Washington County Cogeneration Facility | F9: AL | G9: 0.77 | H9: 0.698 | I9: Yes | J9: No / invalid | K9: 810526 | L9: 3591230 | M9: 4.4307 | N9: CA/NG, CT/NG | O9: 1, 2 | P9: 100 | Q9: Candidate only – do not treat as matched | R9: https://www.eia.gov/electricity/data/eia923/ | S9: https://www.eia.gov/electricity/data/eia860/ | T9: =T8+P9 -> 1165.6
A10: WASHINGTON 2 | B10: Gas Combined Cycle | C10: 3 | D10: 7697 | E10: Washington County Cogeneration Facility | F10: AL | G10: 0.77 | H10: 0.698 | I10: Yes | J10: No / invalid | K10: 810526 | L10: 3591230 | M10: 4.4307 | N10: CA/NG, CT/NG | O10: 1, 2 | P10: 100 | Q10: Candidate only – do not treat as matched | R10: https://www.eia.gov/electricity/data/eia923/ | S10: https://www.eia.gov/electricity/data/eia860/ | T10: =T9+P10 -> 1265.6
A11: WASHINGTON 3 | B11: Gas Combined Cycle | C11: 3 | D11: 7697 | E11: Washington County Cogeneration Facility | F11: AL | G11: 0.77 | H11: 0.698 | I11: Yes | J11: No / invalid | K11: 810526 | L11: 3591230 | M11: 4.4307 | N11: CA/NG, CT/NG | O11: 1, 2 | P11: 100 | Q11: Candidate only – do not treat as matched | R11: https://www.eia.gov/electricity/data/eia923/ | S11: https://www.eia.gov/electricity/data/eia860/ | T11: =T10+P11 -> 1365.6
A12: BRUNNER ISLAND 1 | B12: Steam | C12: 3 | D12: 50479 | E12: Georgia-Pacific Big Island | F12: VA | G12: 0.4385 | H12: 0.4845 | I12: Yes | J12: No / invalid | K12: 23305.248 | L12: 107293 | M12: 4.6038 | N12: ST/NG | O12: GEN1 | P12: 7 | Q12: Candidate only – do not treat as matched | R12: https://www.eia.gov/electricity/data/eia923/ | S12: https://www.eia.gov/electricity/data/eia860/ | T12: =T11+P12 -> 1372.6
A13: BRUNNER ISLAND 2 | B13: Steam | C13: 3 | D13: 50479 | E13: Georgia-Pacific Big Island | F13: VA | G13: 0.4385 | H13: 0.4845 | I13: Yes | J13: No / invalid | K13: 23305.248 | L13: 107293 | M13: 4.6038 | N13: ST/NG | O13: GEN1 | P13: 7 | Q13: Candidate only – do not treat as matched | R13: https://www.eia.gov/electricity/data/eia923/ | S13: https://www.eia.gov/electricity/data/eia860/ | T13: =T12+P13 -> 1379.6
A14: BRUNNER ISLAND 3 | B14: Steam | C14: 3 | D14: 50479 | E14: Georgia-Pacific Big Island | F14: VA | G14: 0.4385 | H14: 0.4845 | I14: Yes | J14: No / invalid | K14: 23305.248 | L14: 107293 | M14: 4.6038 | N14: ST/NG | O14: GEN1 | P14: 7 | Q14: Candidate only – do not treat as matched | R14: https://www.eia.gov/electricity/data/eia923/ | S14: https://www.eia.gov/electricity/data/eia860/ | T14: =T13+P14 -> 1386.6
A15: WHEELABRATOR FALLS | B15: Steam | C15: 3 | D15: 10504 | E15: Amalgamated Sugar Twin Falls | F15: ID | G15: 0.4123 | H15: 0.3403 | I15: Yes | J15: No / invalid | K15: 20649.333 | L15: 101901 | M15: 4.9348 | N15: ST/NG | O15: 1500, 2000, 2500, 4000 | P15: 10.5 | Q15: Candidate only – do not treat as matched | R15: https://www.eia.gov/electricity/data/eia923/ | S15: https://www.eia.gov/electricity/data/eia860/ | T15: =T14+P15 -> 1397.1
A16: EAST BEND 2 | B16: Coal | C16: 3 | D16: 54214 | E16: American Crystal Sugar East Grand Forks | F16: MN | G16: 0.3925 | H16: 0.3205 | I16: Yes | J16: No / invalid | K16: 42576 | L16: 242116 | M16: 5.6867 | N16: ST/SUB | O16: G1, G2 | P16: 7.5 | Q16: Candidate only – do not treat as matched | R16: https://www.eia.gov/electricity/data/eia923/ | S16: https://www.eia.gov/electricity/data/eia860/ | T16: =T15+P16 -> 1404.6
A17: KENDALL CC 1 | B17: Gas Combined Cycle | C17: 2 | D17: 1595 | E17: Kendall Square Station | F17: MA | G17: 0.835 | H17: 0.763 | I17: Yes | J17: Yes | K17: 1533755 | L17: 8963771 | M17: 5.8443 | N17: CA/DFO, CA/NG, CT/DFO, CT/NG | O17: 3, GEN4 | P17: 206 | Q17: Candidate only – do not treat as matched | R17: https://www.eia.gov/electricity/data/eia923/ | S17: https://www.eia.gov/electricity/data/eia860/ | T17: =T16+P17 -> 1610.6
A18: KENDALL CC 2 | B18: Gas Combined Cycle | C18: 2 | D18: 1595 | E18: Kendall Square Station | F18: MA | G18: 0.835 | H18: 0.763 | I18: Yes | J18: Yes | K18: 1533755 | L18: 8963771 | M18: 5.8443 | N18: CA/DFO, CA/NG, CT/DFO, CT/NG | O18: 3, GEN4 | P18: 206 | Q18: Candidate only – do not treat as matched | R18: https://www.eia.gov/electricity/data/eia923/ | S18: https://www.eia.gov/electricity/data/eia860/ | T18: =T17+P18 -> 1816.6
A19: KENDALL CC 3 | B19: Gas Combined Cycle | C19: 2 | D19: 1595 | E19: Kendall Square Station | F19: MA | G19: 0.835 | H19: 0.763 | I19: Yes | J19: Yes | K19: 1533755 | L19: 8963771 | M19: 5.8443 | N19: CA/DFO, CA/NG, CT/DFO, CT/NG | O19: 3, GEN4 | P19: 206 | Q19: Candidate only – do not treat as matched | R19: https://www.eia.gov/electricity/data/eia923/ | S19: https://www.eia.gov/electricity/data/eia860/ | T19: =T18+P19 -> 2022.6
A20: KENDALL CC 4 | B20: Gas Combined Cycle | C20: 2 | D20: 1595 | E20: Kendall Square Station | F20: MA | G20: 0.835 | H20: 0.763 | I20: Yes | J20: Yes | K20: 1533755 | L20: 8963771 | M20: 5.8443 | N20: CA/DFO, CA/NG, CT/DFO, CT/NG | O20: 3, GEN4 | P20: 206 | Q20: Candidate only – do not treat as matched | R20: https://www.eia.gov/electricity/data/eia923/ | S20: https://www.eia.gov/electricity/data/eia860/ | T20: =T19+P20 -> 2228.6
... A46: MIDDLETOWN CC | B46: Gas Combined Cycle | C46: 1 | D46: 60376 | E46: Middletown- Ohio | F46: OH | G46: 0.859 | H46: 0.905 | I46: Yes | J46: Yes | K46: 6529885.6 | L46: 43153278 | M46: 6.6086 | N46: CA/NG, CT/NG | O46: CTG1, CTG2, STG1 | P46: 856.5 | Q46: Candidate only – do not treat as matched | R46: https://www.eia.gov/electricity/data/eia923/ | S46: https://www.eia.gov/electricity/data/eia860/ | T46: =T45+P46 -> 32082.7
A47: HARRISBURG STEAM NUG | B47: Steam | C47: 1 | D47: 10118 | E47: Harrisburg Facility | F47: PA | G47: 0.665 | H47: 0.683 | I47: No | J47: Yes | K47: 5365.7 | L47: 35477 | M47: 6.6118 | N47: ST/NG | P47: 0 | Q47: Candidate only – do not treat as matched | R47: https://www.eia.gov/electricity/data/eia923/ | S47: https://www.eia.gov/electricity/data/eia860/ | T47: =T46+P47 -> 32082.7
A48: HICKORY RUN | B48: Gas Combined Cycle | C48: 1 | D48: 61028 | E48: Hickory Run Energy Station | F48: PA | G48: 1 | H48: 1 | I48: Yes | J48: Yes | K48: 6668580 | L48: 44175102 | M48: 6.6244 | N48: CA/NG, CT/NG | O48: CTG1, CTG2, STG1 | P48: 962.3 | Q48: Accepted: high plant/group proxy | R48: https://www.eia.gov/electricity/data/eia923/ | S48: https://www.eia.gov/electricity/data/eia860/ | T48: =T47+P48 -> 33045
A49: GUERNSEY COUNTY CC 1 | B49: Gas Combined Cycle | C49: 1 | D49: 62949 | E49: Guernsey Power Station | F49: OH | G49: 0.6402 | H49: 0.6862 | I49: Yes | J49: Yes | K49: 11309051 | L49: 75101830 | M49: 6.6409 | N49: CS/NG | O49: GPS1, GPS2, GPS3 | P49: 1788.5 | Q49: Accepted: medium plant/group proxy | R49: https://www.eia.gov/electricity/data/eia923/ | S49: https://www.eia.gov/electricity/data/eia860/ | T49: =T48+P49 -> 34833.5
A50: GUERNSEY COUNTY CC 2 | B50: Gas Combined Cycle | C50: 1 | D50: 62949 | E50: Guernsey Power Station | F50: OH | G50: 0.6402 | H50: 0.6862 | I50: Yes | J50: Yes | K50: 11309051 | L50: 75101830 | M50: 6.6409 | N50: CS/NG | O50: GPS1, GPS2, GPS3 | P50: 1788.5 | Q50: Accepted: medium plant/group proxy | R50: https://www.eia.gov/electricity/data/eia923/ | S50: https://www.eia.gov/electricity/data/eia860/ | T50: =T49+P50 -> 36622
A51: GUERNSEY COUNTY CC 3 | B51: Gas Combined Cycle | C51: 1 | D51: 62949 | E51: Guernsey Power Station | F51: OH | G51: 0.6402 | H51: 0.6862 | I51: Yes | J51: Yes | K51: 11309051 | L51: 75101830 | M51: 6.6409 | N51: CS/NG | O51: GPS1, GPS2, GPS3 | P51: 1788.5 | Q51: Accepted: medium plant/group proxy | R51: https://www.eia.gov/electricity/data/eia923/ | S51: https://www.eia.gov/electricity/data/eia860/ | T51: =T50+P51 -> 38410.5
A52: MOXIE PATRIOT | B52: Gas Combined Cycle | C52: 1 | D52: 58426 | E52: Hamilton Patriot Generation Plant | F52: PA | G52: 0.5341 | H52: 0.5801 | I52: Yes | J52: Yes | K52: 6102059 | L52: 40765309 | M52: 6.6806 | N52: CS/NG | O52: GEN1, GEN2 | P52: 795 | Q52: Candidate only – do not treat as matched | R52: https://www.eia.gov/electricity/data/eia923/ | S52: https://www.eia.gov/electricity/data/eia860/ | T52: =T51+P52 -> 39205.5
A53: FOUR RIVERS 5 | B53: Gas Combined Cycle | C53: 1 | D53: 63931 | E53: CPV Three Rivers Energy Center | F53: IL | G53: 0.4422 | H53: 0.4882 | I53: Yes | J53: Yes | K53: 6456046 | L53: 43371450 | M53: 6.718 | N53: CS/NG | O53: GEN1, GEN2 | P53: 1220.9 | Q53: Candidate only – do not treat as matched | R53: https://www.eia.gov/electricity/data/eia923/ | S53: https://www.eia.gov/electricity/data/eia860/ | T53: =T52+P53 -> 40426.4
A54: THREE RIVERS CC | B54: Gas Combined Cycle | C54: 1 | D54: 63931 | E54: CPV Three Rivers Energy Center | F54: IL | G54: 0.8384 | H54: 0.8844 | I54: Yes | J54: Yes | K54: 6456046 | L54: 43371450 | M54: 6.718 | N54: CS/NG | O54: GEN1, GEN2 | P54: 1220.9 | Q54: Accepted: high plant/group proxy | R54: https://www.eia.gov/electricity/data/eia923/ | S54: https://www.eia.gov/electricity/data/eia860/ | T54: =T53+P54 -> 41647.3
A55: HICKORY RUN | B55: Gas Combined Cycle | C55: 2 | D55: 1363 | E55: Cane Run | F55: KY | G55: 0.5047 | H55: 0.5507 | I55: Yes | J55: Yes | K55: 5128350 | L55: 34557757 | M55: 6.7386 | N55: CA/NG, CT/NG | O55: 7A, 7B, 7S | P55: 691 | Q55: Candidate only – do not treat as matched | R55: https://www.eia.gov/electricity/data/eia923/ | S55: https://www.eia.gov/electricity/data/eia860/ | T55: =T54+P55 -> 42338.3
A56: ST JOSEPH COUNTY CC | B56: Gas Combined Cycle | C56: 1 | D56: 57794 | E56: St Joseph Energy Center | F56: IN | G56: 0.5485 | H56: 0.5945 | I56: Yes | J56: Yes | K56: 5335234 | L56: 36167541 | M56: 6.779 | N56: CA/NG, CT/NG | O56: CT1, CT2, ST1 | P56: 715 | Q56: Candidate only – do not treat as matched | R56: https://www.eia.gov/electricity/data/eia923/ | S56: https://www.eia.gov/electricity/data/eia860/ | T56: =T55+P56 -> 43053.3
A57: DRESDEN CT 1 | B57: Gas Combined Cycle | C57: 1 | D57: 55350 | E57: Dresden Energy Facility | F57: OH | G57: 1 | H57: 1 | I57: Yes | J57: Yes | K57: 4189180 | L57: 28402131 | M57: 6.7799 | N57: CA/NG, CT/NG | O57: 1, 2, 3 | P57: 540 | Q57: Accepted: high plant/group proxy | R57: https://www.eia.gov/electricity/data/eia923/ | S57: https://www.eia.gov/electricity/data/eia860/ | T57: =T56+P57 -> 43593.3
A58: DRESDEN CT 2 | B58: Gas Combined Cycle | C58: 1 | D58: 55350 | E58: Dresden Energy Facility | F58: OH | G58: 1 | H58: 1 | I58: Yes | J58: Yes | K58: 4189180 | L58: 28402131 | M58: 6.7799 | N58: CA/NG, CT/NG | O58: 1, 2, 3 | P58: 540 | Q58: Accepted: high plant/group proxy | R58: https://www.eia.gov/electricity/data/eia923/ | S58: https://www.eia.gov/electricity/data/eia860/ | T58: =T57+P58 -> 44133.3
A59: DRESDEN ST 1 | B59: Gas Combined Cycle | C59: 1 | D59: 55350 | E59: Dresden Energy Facility | F59: OH | G59: 1 | H59: 1 | I59: Yes | J59: Yes | K59: 4189180 | L59: 28402131 | M59: 6.7799 | N59: CA/NG, CT/NG | O59: 1, 2, 3 | P59: 540 | Q59: Accepted: high plant/group proxy | R59: https://www.eia.gov/electricity/data/eia923/ | S59: https://www.eia.gov/electricity/data/eia860/ | T59: =T58+P59 -> 44673.3
... A252: NORTH LONGVIEW | B252: Coal | C252: 1 | D252: 56671 | E252: Longview Power Plant | F252: WV | G252: 0.6459 | H252: 0.6919 | I252: Yes | J252: Yes | K252: 4615575 | L252: 40460006 | M252: 8.766 | N252: ST/BIT | O252: MKA01 | P252: 710 | Q252: Accepted: medium plant/group proxy | R252: https://www.eia.gov/electricity/data/eia923/ | S252: https://www.eia.gov/electricity/data/eia860/ | T252: =T251+P252 -> 198325.6
A253: PAXTON CREEK | B253: Diesel Utility | C253: 1 | D253: 50373 | E253: Paxton Creek Cogeneration | F253: PA | G253: 0.8668 | H253: 0.8848 | I253: No | J253: Yes | K253: 1228.086 | L253: 10926 | M253: 8.8968 | N253: IC/DFO | P253: 0 | Q253: Candidate only – do not treat as matched | R253: https://www.eia.gov/electricity/data/eia923/ | S253: https://www.eia.gov/electricity/data/eia860/ | T253: =T252+P253 -> 198325.6
A254: HOPEWELL HCF | B254: Gas Combined Cycle Dual | C254: 1 | D254: 10633 | E254: Hopewell Cogeneration | F254: VA | G254: 0.5191 | H254: 0.5651 | I254: Yes | J254: Yes | K254: 1773262 | L254: 15790787 | M254: 8.9049 | N254: CA/DFO, CA/NG, CT/DFO, CT/NG | O254: GT1, GT2, GT3, ST1 | P254: 378.3 | Q254: Candidate only – do not treat as matched | R254: https://www.eia.gov/electricity/data/eia923/ | S254: https://www.eia.gov/electricity/data/eia860/ | T254: =T253+P254 -> 198703.9
A255: ERIE COUNTY LF | B255: Landfill Intermittent | C255: 3 | D255: 56280 | E255: Hardin County LFGTE | F255: KY | G255: 0.4042 | H255: 0.4502 | I255: Yes | J255: Yes | K255: 3997 | L255: 36662 | M255: 9.1724 | N255: IC/LFG | O255: 1, 2, 3 | P255: 2.4 | Q255: Candidate only – do not treat as matched | R255: https://www.eia.gov/electricity/data/eia923/ | S255: https://www.eia.gov/electricity/data/eia860/ | T255: =T254+P255 -> 198706.3
